{"uuid": "ee49533f-b40b-4fb4-b40b-6064e6e24ebb", "children": ["71dc5892-834a-4c26-b119-55644cb3cbc8", "355cb0f3-95a4-49d5-9586-2cab992233e9", "6422650d-607f-447a-8207-0c53a66fd86f"], "befores": [{"name": "xunit_setup_class_fixture_TestLogin", "status": "broken", "statusDetails": {"message": "TypeError: 'init' object is not callable\n", "trace": "  File \"/Users/jike/PycharmProjects/pythonProject/venv/lib/python3.9/site-packages/pluggy/_callers.py\", line 39, in _multicall\n    res = hook_impl.function(*args)\n  File \"/Users/jike/PycharmProjects/pythonProject/venv/lib/python3.9/site-packages/_pytest/fixtures.py\", line 1126, in pytest_fixture_setup\n    result = call_fixture_func(fixturefunc, request, kwargs)\n  File \"/Users/jike/PycharmProjects/pythonProject/venv/lib/python3.9/site-packages/_pytest/fixtures.py\", line 925, in call_fixture_func\n    fixture_result = next(generator)\n  File \"/Users/jike/PycharmProjects/pythonProject/venv/lib/python3.9/site-packages/_pytest/python.py\", line 811, in xunit_setup_class_fixture\n    _call_with_optional_argument(func, self.obj)\n  File \"/Users/jike/PycharmProjects/pythonProject/venv/lib/python3.9/site-packages/_pytest/python.py\", line 739, in _call_with_optional_argument\n    func(arg)\n  File \"/Users/jike/PycharmProjects/pythonProject/tests/test_00_login.py\", line 17, in setup_class\n    init().activate_app()\n"}, "start": 1656053218087, "stop": 1656053218087}], "start": 1656053218087, "stop": 1656053218168}